Hi
 * Serving Flask app 'http_server'
 * Debug mode: on
Address already in use
Port 8080 is in use by another program. Either identify and stop that program, or start the server with a different port.
Hi
 * Serving Flask app 'http_server'
 * Debug mode: on
Address already in use
Port 8080 is in use by another program. Either identify and stop that program, or start the server with a different port.
 * Serving Flask app 'http_server'
 * Debug mode: on
WARNING: This is a development server. Do not use it in a production deployment. Use a production WSGI server instead.
 * Running on http://127.0.0.1:8080
Press CTRL+C to quit
 * Restarting with stat
 * Debugger is active!
 * Debugger PIN: 395-936-381
127.0.0.1 - - [31/Jul/2024 08:49:24] "POST /api/post HTTP/1.1" 200 -
127.0.0.1 - - [31/Jul/2024 08:49:24] "GET /api/fruits HTTP/1.1" 200 -
 * Serving Flask app 'http_server'
 * Debug mode: on
Address already in use
Port 8080 is in use by another program. Either identify and stop that program, or start the server with a different port.
127.0.0.1 - - [31/Jul/2024 08:49:38] "POST /api/post HTTP/1.1" 200 -
127.0.0.1 - - [31/Jul/2024 08:49:38] "GET /api/fruits HTTP/1.1" 200 -
127.0.0.1 - - [31/Jul/2024 08:49:49] "POST /api/post HTTP/1.1" 200 -
127.0.0.1 - - [31/Jul/2024 08:49:49] "GET /api/fruits HTTP/1.1" 200 -
127.0.0.1 - - [31/Jul/2024 08:50:40] "POST /api/post HTTP/1.1" 200 -
127.0.0.1 - - [31/Jul/2024 08:50:40] "GET /api/fruits HTTP/1.1" 200 -
127.0.0.1 - - [31/Jul/2024 08:50:58] "POST /api/shutdown HTTP/1.1" 500 -
Traceback (most recent call last):
  File "/home/cloud/.local/lib/python3.10/site-packages/flask/app.py", line 1498, in __call__
    return self.wsgi_app(environ, start_response)
  File "/home/cloud/.local/lib/python3.10/site-packages/flask/app.py", line 1476, in wsgi_app
    response = self.handle_exception(e)
  File "/home/cloud/.local/lib/python3.10/site-packages/flask/app.py", line 1473, in wsgi_app
    response = self.full_dispatch_request()
  File "/home/cloud/.local/lib/python3.10/site-packages/flask/app.py", line 882, in full_dispatch_request
    rv = self.handle_user_exception(e)
  File "/home/cloud/.local/lib/python3.10/site-packages/flask/app.py", line 880, in full_dispatch_request
    rv = self.dispatch_request()
  File "/home/cloud/.local/lib/python3.10/site-packages/flask/app.py", line 865, in dispatch_request
    return self.ensure_sync(self.view_functions[rule.endpoint])(**view_args)  # type: ignore[no-any-return]
  File "/home/cloud/DataFed/DataFed/common/tests/unit/http_server.py", line 35, in shutdown
    raise RuntimeError('Not running with the Werkzeug Server')
RuntimeError: Not running with the Werkzeug Server
127.0.0.1 - - [31/Jul/2024 08:52:36] "POST /api/shutdown HTTP/1.1" 500 -
Traceback (most recent call last):
  File "/home/cloud/.local/lib/python3.10/site-packages/flask/app.py", line 1498, in __call__
    return self.wsgi_app(environ, start_response)
  File "/home/cloud/.local/lib/python3.10/site-packages/flask/app.py", line 1476, in wsgi_app
    response = self.handle_exception(e)
  File "/home/cloud/.local/lib/python3.10/site-packages/flask/app.py", line 1473, in wsgi_app
    response = self.full_dispatch_request()
  File "/home/cloud/.local/lib/python3.10/site-packages/flask/app.py", line 882, in full_dispatch_request
    rv = self.handle_user_exception(e)
  File "/home/cloud/.local/lib/python3.10/site-packages/flask/app.py", line 880, in full_dispatch_request
    rv = self.dispatch_request()
  File "/home/cloud/.local/lib/python3.10/site-packages/flask/app.py", line 865, in dispatch_request
    return self.ensure_sync(self.view_functions[rule.endpoint])(**view_args)  # type: ignore[no-any-return]
  File "/home/cloud/DataFed/DataFed/common/tests/unit/http_server.py", line 35, in shutdown
    raise RuntimeError('Not running with the Werkzeug Server')
RuntimeError: Not running with the Werkzeug Server
 * Serving Flask app 'http_server'
 * Debug mode: on
Address already in use
Port 8080 is in use by another program. Either identify and stop that program, or start the server with a different port.
127.0.0.1 - - [31/Jul/2024 08:52:44] "POST /api/shutdown HTTP/1.1" 500 -
Traceback (most recent call last):
  File "/home/cloud/.local/lib/python3.10/site-packages/flask/app.py", line 1498, in __call__
    return self.wsgi_app(environ, start_response)
  File "/home/cloud/.local/lib/python3.10/site-packages/flask/app.py", line 1476, in wsgi_app
    response = self.handle_exception(e)
  File "/home/cloud/.local/lib/python3.10/site-packages/flask/app.py", line 1473, in wsgi_app
    response = self.full_dispatch_request()
  File "/home/cloud/.local/lib/python3.10/site-packages/flask/app.py", line 882, in full_dispatch_request
    rv = self.handle_user_exception(e)
  File "/home/cloud/.local/lib/python3.10/site-packages/flask/app.py", line 880, in full_dispatch_request
    rv = self.dispatch_request()
  File "/home/cloud/.local/lib/python3.10/site-packages/flask/app.py", line 865, in dispatch_request
    return self.ensure_sync(self.view_functions[rule.endpoint])(**view_args)  # type: ignore[no-any-return]
  File "/home/cloud/DataFed/DataFed/common/tests/unit/http_server.py", line 35, in shutdown
    raise RuntimeError('Not running with the Werkzeug Server')
RuntimeError: Not running with the Werkzeug Server
 * Detected change in '/home/cloud/DataFed/DataFed/common/tests/unit/http_server.py', reloading
 * Restarting with stat
 * Debugger is active!
 * Debugger PIN: 395-936-381
127.0.0.1 - - [31/Jul/2024 08:56:45] "POST /api/post HTTP/1.1" 200 -
127.0.0.1 - - [31/Jul/2024 08:56:45] "GET /api/fruits HTTP/1.1" 200 -
127.0.0.1 - - [31/Jul/2024 08:56:45] "POST /api/shutdown HTTP/1.1" 500 -
Traceback (most recent call last):
  File "/home/cloud/.local/lib/python3.10/site-packages/flask/app.py", line 1498, in __call__
    return self.wsgi_app(environ, start_response)
  File "/home/cloud/.local/lib/python3.10/site-packages/flask/app.py", line 1476, in wsgi_app
    response = self.handle_exception(e)
  File "/home/cloud/.local/lib/python3.10/site-packages/flask/app.py", line 1473, in wsgi_app
    response = self.full_dispatch_request()
  File "/home/cloud/.local/lib/python3.10/site-packages/flask/app.py", line 882, in full_dispatch_request
    rv = self.handle_user_exception(e)
  File "/home/cloud/.local/lib/python3.10/site-packages/flask/app.py", line 880, in full_dispatch_request
    rv = self.dispatch_request()
  File "/home/cloud/.local/lib/python3.10/site-packages/flask/app.py", line 865, in dispatch_request
    return self.ensure_sync(self.view_functions[rule.endpoint])(**view_args)  # type: ignore[no-any-return]
  File "/home/cloud/DataFed/DataFed/common/tests/unit/http_server.py", line 38, in shutdown
    os.kill(os.getpid(), signal.SIGINT)
NameError: name 'os' is not defined
127.0.0.1 - - [31/Jul/2024 10:38:20] "POST /api/post HTTP/1.1" 200 -
127.0.0.1 - - [31/Jul/2024 10:38:20] "GET /api/fruits HTTP/1.1" 200 -
127.0.0.1 - - [31/Jul/2024 10:38:20] "POST /api/shutdown HTTP/1.1" 500 -
Traceback (most recent call last):
  File "/home/cloud/.local/lib/python3.10/site-packages/flask/app.py", line 1498, in __call__
    return self.wsgi_app(environ, start_response)
  File "/home/cloud/.local/lib/python3.10/site-packages/flask/app.py", line 1476, in wsgi_app
    response = self.handle_exception(e)
  File "/home/cloud/.local/lib/python3.10/site-packages/flask/app.py", line 1473, in wsgi_app
    response = self.full_dispatch_request()
  File "/home/cloud/.local/lib/python3.10/site-packages/flask/app.py", line 882, in full_dispatch_request
    rv = self.handle_user_exception(e)
  File "/home/cloud/.local/lib/python3.10/site-packages/flask/app.py", line 880, in full_dispatch_request
    rv = self.dispatch_request()
  File "/home/cloud/.local/lib/python3.10/site-packages/flask/app.py", line 865, in dispatch_request
    return self.ensure_sync(self.view_functions[rule.endpoint])(**view_args)  # type: ignore[no-any-return]
  File "/home/cloud/DataFed/DataFed/common/tests/unit/http_server.py", line 38, in shutdown
    os.kill(os.getpid(), signal.SIGINT)
NameError: name 'os' is not defined
127.0.0.1 - - [31/Jul/2024 10:51:09] "POST /api/post HTTP/1.1" 200 -
127.0.0.1 - - [31/Jul/2024 10:51:09] "GET /api/fruits HTTP/1.1" 200 -
127.0.0.1 - - [31/Jul/2024 10:51:09] "POST /api/shutdown HTTP/1.1" 500 -
Traceback (most recent call last):
  File "/home/cloud/.local/lib/python3.10/site-packages/flask/app.py", line 1498, in __call__
    return self.wsgi_app(environ, start_response)
  File "/home/cloud/.local/lib/python3.10/site-packages/flask/app.py", line 1476, in wsgi_app
    response = self.handle_exception(e)
  File "/home/cloud/.local/lib/python3.10/site-packages/flask/app.py", line 1473, in wsgi_app
    response = self.full_dispatch_request()
  File "/home/cloud/.local/lib/python3.10/site-packages/flask/app.py", line 882, in full_dispatch_request
    rv = self.handle_user_exception(e)
  File "/home/cloud/.local/lib/python3.10/site-packages/flask/app.py", line 880, in full_dispatch_request
    rv = self.dispatch_request()
  File "/home/cloud/.local/lib/python3.10/site-packages/flask/app.py", line 865, in dispatch_request
    return self.ensure_sync(self.view_functions[rule.endpoint])(**view_args)  # type: ignore[no-any-return]
  File "/home/cloud/DataFed/DataFed/common/tests/unit/http_server.py", line 38, in shutdown
    os.kill(os.getpid(), signal.SIGINT)
NameError: name 'os' is not defined
127.0.0.1 - - [31/Jul/2024 11:21:01] "GET /api/fruits HTTP/1.1" 200 -
127.0.0.1 - - [31/Jul/2024 11:21:01] "GET /api/fruits HTTP/1.1" 200 -
127.0.0.1 - - [31/Jul/2024 11:21:01] "POST /api/shutdown HTTP/1.1" 500 -
Traceback (most recent call last):
  File "/home/cloud/.local/lib/python3.10/site-packages/flask/app.py", line 1498, in __call__
    return self.wsgi_app(environ, start_response)
  File "/home/cloud/.local/lib/python3.10/site-packages/flask/app.py", line 1476, in wsgi_app
    response = self.handle_exception(e)
  File "/home/cloud/.local/lib/python3.10/site-packages/flask/app.py", line 1473, in wsgi_app
    response = self.full_dispatch_request()
  File "/home/cloud/.local/lib/python3.10/site-packages/flask/app.py", line 882, in full_dispatch_request
    rv = self.handle_user_exception(e)
  File "/home/cloud/.local/lib/python3.10/site-packages/flask/app.py", line 880, in full_dispatch_request
    rv = self.dispatch_request()
  File "/home/cloud/.local/lib/python3.10/site-packages/flask/app.py", line 865, in dispatch_request
    return self.ensure_sync(self.view_functions[rule.endpoint])(**view_args)  # type: ignore[no-any-return]
  File "/home/cloud/DataFed/DataFed/common/tests/unit/http_server.py", line 38, in shutdown
    os.kill(os.getpid(), signal.SIGINT)
NameError: name 'os' is not defined
127.0.0.1 - - [31/Jul/2024 13:40:26] "POST /api/post HTTP/1.1" 200 -
127.0.0.1 - - [31/Jul/2024 13:40:26] "GET /api/fruits HTTP/1.1" 200 -
127.0.0.1 - - [31/Jul/2024 13:40:26] "POST /api/shutdown HTTP/1.1" 500 -
Traceback (most recent call last):
  File "/home/cloud/.local/lib/python3.10/site-packages/flask/app.py", line 1498, in __call__
    return self.wsgi_app(environ, start_response)
  File "/home/cloud/.local/lib/python3.10/site-packages/flask/app.py", line 1476, in wsgi_app
    response = self.handle_exception(e)
  File "/home/cloud/.local/lib/python3.10/site-packages/flask/app.py", line 1473, in wsgi_app
    response = self.full_dispatch_request()
  File "/home/cloud/.local/lib/python3.10/site-packages/flask/app.py", line 882, in full_dispatch_request
    rv = self.handle_user_exception(e)
  File "/home/cloud/.local/lib/python3.10/site-packages/flask/app.py", line 880, in full_dispatch_request
    rv = self.dispatch_request()
  File "/home/cloud/.local/lib/python3.10/site-packages/flask/app.py", line 865, in dispatch_request
    return self.ensure_sync(self.view_functions[rule.endpoint])(**view_args)  # type: ignore[no-any-return]
  File "/home/cloud/DataFed/DataFed/common/tests/unit/http_server.py", line 38, in shutdown
    os.kill(os.getpid(), signal.SIGINT)
NameError: name 'os' is not defined
